<?xml version="1.0" encoding="UTF-8"?>
<!-- Generated by org.testng.reporters.JUnitReportReporter -->
<testsuite hostname="LAPTOP-DNHRTNE3" name="Jan4.Demo_Extenreport" tests="4" failures="3" timestamp="8 Jan 2020 17:03:06 GMT" time="1.108" errors="1">
  <testcase name="demoTestPass1" time="0.093" classname="Jan4.Demo_Extenreport">
    <failure type="java.lang.AssertionError" message="expected [false] but found [true]">
      <![CDATA[java.lang.AssertionError: expected [false] but found [true]
	at org.testng.Assert.fail(Assert.java:94)
	at org.testng.Assert.failNotEquals(Assert.java:496)
	at org.testng.Assert.assertFalse(Assert.java:63)
	at org.testng.Assert.assertFalse(Assert.java:73)
	at Jan4.Demo_Extenreport.demoTestPass1(Demo_Extenreport.java:28)
	at sun.reflect.NativeMethodAccessorImpl.invoke0(Native Method)
	at sun.reflect.NativeMethodAccessorImpl.invoke(Unknown Source)
	at sun.reflect.DelegatingMethodAccessorImpl.invoke(Unknown Source)
	at java.lang.reflect.Method.invoke(Unknown Source)
	at org.testng.internal.MethodInvocationHelper.invokeMethod(MethodInvocationHelper.java:85)
	at org.testng.internal.Invoker.invokeMethod(Invoker.java:663)
	at org.testng.internal.Invoker.invokeTestMethod(Invoker.java:849)
	at org.testng.internal.Invoker.invokeTestMethods(Invoker.java:1157)
	at org.testng.internal.TestMethodWorker.invokeTestMethods(TestMethodWorker.java:124)
	at org.testng.internal.TestMethodWorker.run(TestMethodWorker.java:108)
	at org.testng.TestRunner.privateRun(TestRunner.java:771)
	at org.testng.TestRunner.run(TestRunner.java:621)
	at org.testng.SuiteRunner.runTest(SuiteRunner.java:357)
	at org.testng.SuiteRunner.runSequentially(SuiteRunner.java:352)
	at org.testng.SuiteRunner.privateRun(SuiteRunner.java:310)
	at org.testng.SuiteRunner.run(SuiteRunner.java:259)
	at org.testng.SuiteRunnerWorker.runSuite(SuiteRunnerWorker.java:52)
	at org.testng.SuiteRunnerWorker.run(SuiteRunnerWorker.java:86)
	at org.testng.TestNG.runSuitesSequentially(TestNG.java:1200)
	at org.testng.TestNG.runSuitesLocally(TestNG.java:1125)
	at org.testng.TestNG.run(TestNG.java:1033)
	at org.testng.remote.RemoteTestNG.run(RemoteTestNG.java:111)
	at org.testng.remote.RemoteTestNG.initAndRun(RemoteTestNG.java:204)
	at org.testng.remote.RemoteTestNG.main(RemoteTestNG.java:175)
]]>
    </failure>
  </testcase> <!-- demoTestPass1 -->
  <testcase name="demoTestFail" time="0.176" classname="Jan4.Demo_Extenreport">
    <failure type="java.lang.AssertionError" message="expected [true] but found [false]">
      <![CDATA[java.lang.AssertionError: expected [true] but found [false]
	at org.testng.Assert.fail(Assert.java:94)
	at org.testng.Assert.failNotEquals(Assert.java:496)
	at org.testng.Assert.assertTrue(Assert.java:42)
	at org.testng.Assert.assertTrue(Assert.java:52)
	at Jan4.Demo_Extenreport.demoTestFail(Demo_Extenreport.java:42)
	at sun.reflect.NativeMethodAccessorImpl.invoke0(Native Method)
	at sun.reflect.NativeMethodAccessorImpl.invoke(Unknown Source)
	at sun.reflect.DelegatingMethodAccessorImpl.invoke(Unknown Source)
	at java.lang.reflect.Method.invoke(Unknown Source)
	at org.testng.internal.MethodInvocationHelper.invokeMethod(MethodInvocationHelper.java:85)
	at org.testng.internal.Invoker.invokeMethod(Invoker.java:663)
	at org.testng.internal.Invoker.invokeTestMethod(Invoker.java:849)
	at org.testng.internal.Invoker.invokeTestMethods(Invoker.java:1157)
	at org.testng.internal.TestMethodWorker.invokeTestMethods(TestMethodWorker.java:124)
	at org.testng.internal.TestMethodWorker.run(TestMethodWorker.java:108)
	at org.testng.TestRunner.privateRun(TestRunner.java:771)
	at org.testng.TestRunner.run(TestRunner.java:621)
	at org.testng.SuiteRunner.runTest(SuiteRunner.java:357)
	at org.testng.SuiteRunner.runSequentially(SuiteRunner.java:352)
	at org.testng.SuiteRunner.privateRun(SuiteRunner.java:310)
	at org.testng.SuiteRunner.run(SuiteRunner.java:259)
	at org.testng.SuiteRunnerWorker.runSuite(SuiteRunnerWorker.java:52)
	at org.testng.SuiteRunnerWorker.run(SuiteRunnerWorker.java:86)
	at org.testng.TestNG.runSuitesSequentially(TestNG.java:1200)
	at org.testng.TestNG.runSuitesLocally(TestNG.java:1125)
	at org.testng.TestNG.run(TestNG.java:1033)
	at org.testng.remote.RemoteTestNG.run(RemoteTestNG.java:111)
	at org.testng.remote.RemoteTestNG.initAndRun(RemoteTestNG.java:204)
	at org.testng.remote.RemoteTestNG.main(RemoteTestNG.java:175)
]]>
    </failure>
  </testcase> <!-- demoTestFail -->
  <testcase name="demoTestPass2" time="0.783" classname="Jan4.Demo_Extenreport">
    <failure type="java.lang.AssertionError" message="expected [false] but found [true]">
      <![CDATA[java.lang.AssertionError: expected [false] but found [true]
	at org.testng.Assert.fail(Assert.java:94)
	at org.testng.Assert.failNotEquals(Assert.java:496)
	at org.testng.Assert.assertFalse(Assert.java:63)
	at org.testng.Assert.assertFalse(Assert.java:73)
	at Jan4.Demo_Extenreport.demoTestPass2(Demo_Extenreport.java:35)
	at sun.reflect.NativeMethodAccessorImpl.invoke0(Native Method)
	at sun.reflect.NativeMethodAccessorImpl.invoke(Unknown Source)
	at sun.reflect.DelegatingMethodAccessorImpl.invoke(Unknown Source)
	at java.lang.reflect.Method.invoke(Unknown Source)
	at org.testng.internal.MethodInvocationHelper.invokeMethod(MethodInvocationHelper.java:85)
	at org.testng.internal.Invoker.invokeMethod(Invoker.java:663)
	at org.testng.internal.Invoker.invokeTestMethod(Invoker.java:849)
	at org.testng.internal.Invoker.invokeTestMethods(Invoker.java:1157)
	at org.testng.internal.TestMethodWorker.invokeTestMethods(TestMethodWorker.java:124)
	at org.testng.internal.TestMethodWorker.run(TestMethodWorker.java:108)
	at org.testng.TestRunner.privateRun(TestRunner.java:771)
	at org.testng.TestRunner.run(TestRunner.java:621)
	at org.testng.SuiteRunner.runTest(SuiteRunner.java:357)
	at org.testng.SuiteRunner.runSequentially(SuiteRunner.java:352)
	at org.testng.SuiteRunner.privateRun(SuiteRunner.java:310)
	at org.testng.SuiteRunner.run(SuiteRunner.java:259)
	at org.testng.SuiteRunnerWorker.runSuite(SuiteRunnerWorker.java:52)
	at org.testng.SuiteRunnerWorker.run(SuiteRunnerWorker.java:86)
	at org.testng.TestNG.runSuitesSequentially(TestNG.java:1200)
	at org.testng.TestNG.runSuitesLocally(TestNG.java:1125)
	at org.testng.TestNG.run(TestNG.java:1033)
	at org.testng.remote.RemoteTestNG.run(RemoteTestNG.java:111)
	at org.testng.remote.RemoteTestNG.initAndRun(RemoteTestNG.java:204)
	at org.testng.remote.RemoteTestNG.main(RemoteTestNG.java:175)
]]>
    </failure>
  </testcase> <!-- demoTestPass2 -->
  <testcase name="demoTestSkip" time="0.056" classname="Jan4.Demo_Extenreport">
    <error type="org.testng.SkipException" message="This test case not ready for execution">
      <![CDATA[org.testng.SkipException: This test case not ready for execution
	at Jan4.Demo_Extenreport.demoTestSkip(Demo_Extenreport.java:49)
	at sun.reflect.NativeMethodAccessorImpl.invoke0(Native Method)
	at sun.reflect.NativeMethodAccessorImpl.invoke(Unknown Source)
	at sun.reflect.DelegatingMethodAccessorImpl.invoke(Unknown Source)
	at java.lang.reflect.Method.invoke(Unknown Source)
	at org.testng.internal.MethodInvocationHelper.invokeMethod(MethodInvocationHelper.java:85)
	at org.testng.internal.Invoker.invokeMethod(Invoker.java:663)
	at org.testng.internal.Invoker.invokeTestMethod(Invoker.java:849)
	at org.testng.internal.Invoker.invokeTestMethods(Invoker.java:1157)
	at org.testng.internal.TestMethodWorker.invokeTestMethods(TestMethodWorker.java:124)
	at org.testng.internal.TestMethodWorker.run(TestMethodWorker.java:108)
	at org.testng.TestRunner.privateRun(TestRunner.java:771)
	at org.testng.TestRunner.run(TestRunner.java:621)
	at org.testng.SuiteRunner.runTest(SuiteRunner.java:357)
	at org.testng.SuiteRunner.runSequentially(SuiteRunner.java:352)
	at org.testng.SuiteRunner.privateRun(SuiteRunner.java:310)
	at org.testng.SuiteRunner.run(SuiteRunner.java:259)
	at org.testng.SuiteRunnerWorker.runSuite(SuiteRunnerWorker.java:52)
	at org.testng.SuiteRunnerWorker.run(SuiteRunnerWorker.java:86)
	at org.testng.TestNG.runSuitesSequentially(TestNG.java:1200)
	at org.testng.TestNG.runSuitesLocally(TestNG.java:1125)
	at org.testng.TestNG.run(TestNG.java:1033)
	at org.testng.remote.RemoteTestNG.run(RemoteTestNG.java:111)
	at org.testng.remote.RemoteTestNG.initAndRun(RemoteTestNG.java:204)
	at org.testng.remote.RemoteTestNG.main(RemoteTestNG.java:175)
]]>
    </error>
  </testcase> <!-- demoTestSkip -->
</testsuite> <!-- Jan4.Demo_Extenreport -->
